Workbook

Sheet SO DETAILS
E1: LAPORAN STOCK OPNAME HARIAN <BRAND>
E2: SO SEBELUMNYA | H2: SO SEKARANG
A3: CBG01BDG (Bandung) | C3: 05/09/2026 | D3: Shift | E3: Taufik | F3: Closing | H3: CBG01BDG (Bandung) | J3: 05/09/2026 | K3: Shift | L3: Sabat | M3: Opening
A4: INFORMASI BARANG | K4: HASIL ANALISIS
A5: No | B5: NAMA BARANG | C5: SATUAN | D5: THRESHOLD | E5: STEP 1 UTUH | F5: STEP 2 TERBUKA | G5: TOTAL | H5: STEP 1 UTUH | I5: STEP 2 TERBUKA | J5: TOTAL 2 | K5: PEMAKAIAN | L5: STATUS STOK | M5: KETERANGAN
A6: 27 | B6: Dus Hampers | C6: pcs | D6: 2 | E6: 0 | F6: 1 | G6: 1 | H6: 0 | I6: 1 | J6: =H6+I6 -> 1 | K6: =IF(COUNTA(G6,J6)=0,"",IF(J6-G6=0,0,IF(J6-G6>0,"+"&(J6-G6),J6-G6))) -> 0 | L6: =IF(D6=0,"—",IF(J6<=D6,"🔴 KRITIS",IF(J6<=D6*2,"🟠 HAMPIR HABIS","🟢 AMAN"))) -> 🔴 KRITIS
A7: 28 | B7: Box Berbagi | C7: pcs | D7: 2 | E7: 0 | F7: 0 | G7: 0 | H7: 0 | I7: 0 | J7: =H7+I7 -> 0 | K7: =IF(COUNTA(G7,J7)=0,"",IF(J7-G7=0,0,IF(J7-G7>0,"+"&(J7-G7),J7-G7))) -> 0 | L7: =IF(D7=0,"—",IF(J7<=D7,"🔴 KRITIS",IF(J7<=D7*2,"🟠 HAMPIR HABIS","🟢 AMAN"))) -> 🔴 KRITIS
A8: 2 | B8: Bumbu Mix | C8: pcs | D8: ='⚙️ Master Threshold'!E7 -> 1 | E8: 0 | F8: 1 | G8: 1 | H8: 0 | I8: 1 | J8: =H8+I8 -> 1 | K8: =IF(COUNTA(G8,J8)=0,"",IF(J8-G8=0,0,IF(J8-G8>0,"+"&(J8-G8),J8-G8))) -> 0 | L8: =IF(D8=0,"—",IF(J8<=D8,"🔴 KRITIS",IF(J8<=D8*2,"🟠 HAMPIR HABIS","🟢 AMAN"))) -> 🔴 KRITIS
A9: 6 | B9: Mango Mint | C9: gr | D9: ='⚙️ Master Threshold'!E11 -> 8 | E9: 0 | F9: 14 | G9: 7 | H9: 0 | I9: 14 | J9: =H9+I9-7 -> 7 | K9: =IF(COUNTA(G9,J9)=0,"",IF(J9-G9=0,0,IF(J9-G9>0,"+"&(J9-G9),J9-G9))) -> 0 | L9: =IF(D9=0,"—",IF(J9<=D9,"🔴 KRITIS",IF(J9<=D9*2,"🟠 HAMPIR HABIS","🟢 AMAN"))) -> 🔴 KRITIS
A10: 7 | B10: Mint Ice Cream | C10: gr | D10: ='⚙️ Master Threshold'!E12 -> 8 | E10: 0 | F10: 12 | G10: 5 | H10: 0 | I10: 12 | J10: =H10+I10-7 -> 5 | K10: =IF(COUNTA(G10,J10)=0,"",IF(J10-G10=0,0,IF(J10-G10>0,"+"&(J10-G10),J10-G10))) -> 0 | L10: =IF(D10=0,"—",IF(J10<=D10,"🔴 KRITIS",IF(J10<=D10*2,"🟠 HAMPIR HABIS","🟢 AMAN"))) -> 🔴 KRITIS
A11: 9 | B11: Snowy Cheese | C11: gr | D11: ='⚙️ Master Threshold'!E14 -> 380 | E11: 0 | F11: 434 | G11: 319 | H11: 0 | I11: 434 | J11: =H11+I11-115 -> 319 | K11: =IF(COUNTA(G11,J11)=0,"",IF(J11-G11=0,0,IF(J11-G11>0,"+"&(J11-G11),J11-G11))) -> 0 | L11: =IF(D11=0,"—",IF(J11<=D11,"🔴 KRITIS",IF(J11<=D11*2,"🟠 HAMPIR HABIS","🟢 AMAN"))) -> 🔴 KRITIS
A12: 20 | B12: Bon Cabe | C12: pcs | D12: ='⚙️ Master Threshold'!E25 -> 1 | E12: 0 | F12: 0 | G12: 0 | H12: 0 | I12: 0 | J12: =H12+I12 -> 0 | K12: =IF(COUNTA(G12,J12)=0,"",IF(J12-G12=0,0,IF(J12-G12>0,"+"&(J12-G12),J12-G12))) -> 0 | L12: =IF(D12=0,"—",IF(J12<=D12,"🔴 KRITIS",IF(J12<=D12*2,"🟠 HAMPIR HABIS","🟢 AMAN"))) -> 🔴 KRITIS
A13: 21 | B13: Plastik 15 | C13: pax | D13: ='⚙️ Master Threshold'!E26 -> 1 | E13: 0 | F13: 1 | G13: 1 | H13: 0 | I13: 1 | J13: =H13+I13 -> 1 | K13: =IF(COUNTA(G13,J13)=0,"",IF(J13-G13=0,0,IF(J13-G13>0,"+"&(J13-G13),J13-G13))) -> 0 | L13: =IF(D13=0,"—",IF(J13<=D13,"🔴 KRITIS",IF(J13<=D13*2,"🟠 HAMPIR HABIS","🟢 AMAN"))) -> 🔴 KRITIS
A14: 22 | B14: Plastik 24 | C14: pax | D14: ='⚙️ Master Threshold'!E27 -> 1 | E14: 0 | F14: 1 | G14: 1 | H14: 0 | I14: 1 | J14: =H14+I14 -> 1 | K14: =IF(COUNTA(G14,J14)=0,"",IF(J14-G14=0,0,IF(J14-G14>0,"+"&(J14-G14),J14-G14))) -> 0 | L14: =IF(D14=0,"—",IF(J14<=D14,"🔴 KRITIS",IF(J14<=D14*2,"🟠 HAMPIR HABIS","🟢 AMAN"))) -> 🔴 KRITIS
A15: 23 | B15: Plastik 30 | C15: pax | D15: ='⚙️ Master Threshold'!E28 -> 1 | E15: 0 | F15: 1 | G15: 1 | H15: 0 | I15: 1 | J15: =H15+I15 -> 1 | K15: =IF(COUNTA(G15,J15)=0,"",IF(J15-G15=0,0,IF(J15-G15>0,"+"&(J15-G15),J15-G15))) -> 0 | L15: =IF(D15=0,"—",IF(J15<=D15,"🔴 KRITIS",IF(J15<=D15*2,"🟠 HAMPIR HABIS","🟢 AMAN"))) -> 🔴 KRITIS
A16: 31 | B16: Katsubuoshi | C16: gr | D16: ='⚙️ Master Threshold'!E36 -> 5 | E16: 0 | F16: 0 | G16: 0 | H16: 0 | I16: 0 | J16: =H16+I16 -> 0 | K16: =IF(COUNTA(G16,J16)=0,"",IF(J16-G16=0,0,IF(J16-G16>0,"+"&(J16-G16),J16-G16))) -> 0 | L16: =IF(D16=0,"—",IF(J16<=D16,"🔴 KRITIS",IF(J16<=D16*2,"🟠 HAMPIR HABIS","🟢 AMAN"))) -> 🔴 KRITIS
A17: 11 | B17: Tepung Corndog | C17: gr | D17: 100 | E17: 0 | F17: 139 | G17: 139 | H17: 0 | I17: =53+86 -> 139 | J17: =H17+I17 -> 139 | K17: =IF(COUNTA(G17,J17)=0,"",IF(J17-G17=0,0,IF(J17-G17>0,"+"&(J17-G17),J17-G17))) -> 0 | L17: =IF(D17=0,"—",IF(J17<=D17,"🔴 KRITIS",IF(J17<=D17*2,"🟠 HAMPIR HABIS","🟢 AMAN"))) -> 🟠 HAMPIR HABIS
A18: 29 | B18: Botol Hampers | C18: pcs | D18: 2 | E18: 0 | F18: 3 | G18: 3 | H18: 0 | I18: 3 | J18: =H18+I18 -> 3 | K18: =IF(COUNTA(G18,J18)=0,"",IF(J18-G18=0,0,IF(J18-G18>0,"+"&(J18-G18),J18-G18))) -> 0 | L18: =IF(D18=0,"—",IF(J18<=D18,"🔴 KRITIS",IF(J18<=D18*2,"🟠 HAMPIR HABIS","🟢 AMAN"))) -> 🟠 HAMPIR HABIS
A19: 4 | B19: Bumbu Marinasi | C19: gr | D19: ='⚙️ Master Threshold'!E9 -> 125 | E19: 0 | F19: 174 | G19: 174 | H19: 0 | I19: 174 | J19: =H19+I19 -> 174 | K19: =IF(COUNTA(G19,J19)=0,"",IF(J19-G19=0,0,IF(J19-G19>0,"+"&(J19-G19),J19-G19))) -> 0 | L19: =IF(D19=0,"—",IF(J19<=D19,"🔴 KRITIS",IF(J19<=D19*2,"🟠 HAMPIR HABIS","🟢 AMAN"))) -> 🟠 HAMPIR HABIS
A20: 19 | B20: Samyang | C20: gr | D20: ='⚙️ Master Threshold'!E24 -> 45 | E20: 0 | F20: 83 | G20: 83 | H20: 0 | I20: 83 | J20: =H20+I20 -> 83 | K20: =IF(COUNTA(G20,J20)=0,"",IF(J20-G20=0,0,IF(J20-G20>0,"+"&(J20-G20),J20-G20))) -> 0 | L20: =IF(D20=0,"—",IF(J20<=D20,"🔴 KRITIS",IF(J20<=D20*2,"🟠 HAMPIR HABIS","🟢 AMAN"))) -> 🟠 HAMPIR HABIS
A21: 30 | B21: Gas Torch | C21: gr | D21: ='⚙️ Master Threshold'!E35 -> 100 | E21: 0 | F21: 102 | G21: 102 | H21: 0 | I21: 101 | J21: =H21+I21 -> 101 | K21: =IF(COUNTA(G21,J21)=0,"",IF(J21-G21=0,0,IF(J21-G21>0,"+"&(J21-G21),J21-G21))) -> -1 | L21: =IF(D21=0,"—",IF(J21<=D21,"🔴 KRITIS",IF(J21<=D21*2,"🟠 HAMPIR HABIS","🟢 AMAN"))) -> 🟠 HAMPIR HABIS
A22: 32 | B22: Spray Lemon Pepper | C22: gr | D22: ='⚙️ Master Threshold'!E37 -> 40 | E22: 0 | F22: 59 | G22: 59 | H22: 0 | I22: 59 | J22: =H22+I22 -> 59 | K22: =IF(COUNTA(G22,J22)=0,"",IF(J22-G22=0,0,IF(J22-G22>0,"+"&(J22-G22),J22-G22))) -> 0 | L22: =IF(D22=0,"—",IF(J22<=D22,"🔴 KRITIS",IF(J22<=D22*2,"🟠 HAMPIR HABIS","🟢 AMAN"))) -> 🟠 HAMPIR HABIS
A23: 25 | B23: Baking Soda | C23: gr | D23: 5 | E23: 0 | F23: 40 | G23: 40 | H23: 0 | I23: 40 | J23: =H23+I23 -> 40 | K23: =IF(COUNTA(G23,J23)=0,"",IF(J23-G23=0,0,IF(J23-G23>0,"+"&(J23-G23),J23-G23))) -> 0 | L23: =IF(D23=0,"—",IF(J23<=D23,"🔴 KRITIS",IF(J23<=D23*2,"🟠 HAMPIR HABIS","🟢 AMAN"))) -> 🟢 AMAN
A24: 1 | B24: Tepung Terigu | C24: kg | D24: ='⚙️ Master Threshold'!E6 -> 2 | E24: 20 | F24: 0 | G24: 20 | H24: 20 | I24: 0 | J24: =H24+I24 -> 20 | K24: =IF(COUNTA(G24,J24)=0,"",IF(J24-G24=0,0,IF(J24-G24>0,"+"&(J24-G24),J24-G24))) -> 0 | L24: =IF(D24=0,"—",IF(J24<=D24,"🔴 KRITIS",IF(J24<=D24*2,"🟠 HAMPIR HABIS","🟢 AMAN"))) -> 🟢 AMAN
A25: 3 | B25: Minyak liquid | C25: kg -+ | D25: ='⚙️ Master Threshold'!E8 -> 5 | E25: 38 | F25: 0 | G25: 38 | H25: 36 | I25: 17 | J25: =H25+I25 -> 53 | K25: =IF(COUNTA(G25,J25)=0,"",IF(J25-G25=0,0,IF(J25-G25>0,"+"&(J25-G25),J25-G25))) -> +15 | L25: =IF(D25=0,"—",IF(J25<=D25,"🔴 KRITIS",IF(J25<=D25*2,"🟠 HAMPIR HABIS","🟢 AMAN"))) -> 🟢 AMAN
A26: 5 | B26: Beras | C26: kg | D26: ='⚙️ Master Threshold'!E10 -> 1 | E26: 0 | F26: 4 | G26: 4 | H26: 0 | I26: 3 | J26: =H26+I26 -> 3 | K26: =IF(COUNTA(G26,J26)=0,"",IF(J26-G26=0,0,IF(J26-G26>0,"+"&(J26-G26),J26-G26))) -> -1 | L26: =IF(D26=0,"—",IF(J26<=D26,"🔴 KRITIS",IF(J26<=D26*2,"🟠 HAMPIR HABIS","🟢 AMAN"))) -> 🟢 AMAN
A27: 8 | B27: Vanilla Rose | C27: gr | D27: ='⚙️ Master Threshold'!E13 -> 8 | E27: 0 | F27: 39 | G27: 32 | H27: 0 | I27: 39 | J27: =H27+I27-7 -> 32 | K27: =IF(COUNTA(G27,J27)=0,"",IF(J27-G27=0,0,IF(J27-G27>0,"+"&(J27-G27),J27-G27))) -> 0 | L27: =IF(D27=0,"—",IF(J27<=D27,"🔴 KRITIS",IF(J27<=D27*2,"🟠 HAMPIR HABIS","🟢 AMAN"))) -> 🟢 AMAN
A28: 10 | B28: Tepung Panir | C28: gr | D28: ='⚙️ Master Threshold'!E15 -> 125 | E28: 200 | F28: 160 | G28: 360 | H28: 200 | I28: 160 | J28: =H28+I28 -> 360 | K28: =IF(COUNTA(G28,J28)=0,"",IF(J28-G28=0,0,IF(J28-G28>0,"+"&(J28-G28),J28-G28))) -> 0 | L28: =IF(D28=0,"—",IF(J28<=D28,"🔴 KRITIS",IF(J28<=D28*2,"🟠 HAMPIR HABIS","🟢 AMAN"))) -> 🟢 AMAN
A29: 12 | B29: Cabe Sachet | C29: pcs | D29: ='⚙️ Master Threshold'!E17 -> 10 | E29: 24 | F29: 23 | G29: 47 | H29: 24 | I29: 23 | J29: =H29+I29 -> 47 | K29: =IF(COUNTA(G29,J29)=0,"",IF(J29-G29=0,0,IF(J29-G29>0,"+"&(J29-G29),J29-G29))) -> 0 | L29: =IF(D29=0,"—",IF(J29<=D29,"🔴 KRITIS",IF(J29<=D29*2,"🟠 HAMPIR HABIS","🟢 AMAN"))) -> 🟢 AMAN
A30: 13 | B30: Tomat Sachet | C30: pcs | D30: ='⚙️ Master Threshold'!E18 -> 10 | E30: 48 | F30: 16 | G30: 64 | H30: 48 | I30: 16 | J30: =H30+I30 -> 64 | K30: =IF(COUNTA(G30,J30)=0,"",IF(J30-G30=0,0,IF(J30-G30>0,"+"&(J30-G30),J30-G30))) -> 0 | L30: =IF(D30=0,"—",IF(J30<=D30,"🔴 KRITIS",IF(J30<=D30*2,"🟠 HAMPIR HABIS","🟢 AMAN"))) -> 🟢 AMAN
A31: 14 | B31: Nori | C31: gr | D31: ='⚙️ Master Threshold'!E19 -> 30 | E31: 41 | F31: 28 | G31: 69 | H31: 41 | I31: 28 | J31: =H31+I31 -> 69 | K31: =IF(COUNTA(G31,J31)=0,"",IF(J31-G31=0,0,IF(J31-G31>0,"+"&(J31-G31),J31-G31))) -> 0 | L31: =IF(D31=0,"—",IF(J31<=D31,"🔴 KRITIS",IF(J31<=D31*2,"🟠 HAMPIR HABIS","🟢 AMAN"))) -> 🟢 AMAN
A32: 15 | B32: Biji Wijen | C32: gr | D32: ='⚙️ Master Threshold'!E20 -> 30 | E32: 129 | F32: 68 | G32: 197 | H32: 129 | I32: 68 | J32: =H32+I32 -> 197 | K32: =IF(COUNTA(G32,J32)=0,"",IF(J32-G32=0,0,IF(J32-G32>0,"+"&(J32-G32),J32-G32))) -> 0 | L32: =IF(D32=0,"—",IF(J32<=D32,"🔴 KRITIS",IF(J32<=D32*2,"🟠 HAMPIR HABIS","🟢 AMAN"))) -> 🟢 AMAN
A33: 16 | B33: Gula Putih | C33: gr | D33: ='⚙️ Master Threshold'!E21 -> 100 | E33: 0 | F33: 459 | G33: 459 | H33: 0 | I33: 459 | J33: =H33+I33 -> 459 | K33: =IF(COUNTA(G33,J33)=0,"",IF(J33-G33=0,0,IF(J33-G33>0,"+"&(J33-G33),J33-G33))) -> 0 | L33: =IF(D33=0,"—",IF(J33<=D33,"🔴 KRITIS",IF(J33<=D33*2,"🟠 HAMPIR HABIS","🟢 AMAN"))) -> 🟢 AMAN
A34: 17 | B34: Garam | C34: gr | D34: ='⚙️ Master Threshold'!E22 -> 20 | E34: 104 | F34: 550 | G34: 654 | H34: 104 | I34: 550 | J34: =H34+I34 -> 654 | K34: =IF(COUNTA(G34,J34)=0,"",IF(J34-G34=0,0,IF(J34-G34>0,"+"&(J34-G34),J34-G34))) -> 0 | L34: =IF(D34=0,"—",IF(J34<=D34,"🔴 KRITIS",IF(J34<=D34*2,"🟠 HAMPIR HABIS","🟢 AMAN"))) -> 🟢 AMAN
A35: 25 | B35: Cheese Tteokbokki | C35: gr | D35: ='⚙️ Master Threshold'!E63 -> 75 | E35: 209 | F35: 76 | G35: 260 | H35: 209 | I35: 76 | J35: =H35+I35-25 -> 260 | K35: =IF(COUNTA(G35,J35)=0,"",IF(J35-G35=0,0,IF(J35-G35>0,"+"&(J35-G35),J35-G35))) -> 0 | L35: =IF(D35=0,"—",IF(J35<=D35,"🔴 KRITIS",IF(J35<=D35*2,"🟠 HAMPIR HABIS","🟢 AMAN"))) -> 🟢 AMAN
A36: 18 | B36: Cajun | C36: gr | D36: ='⚙️ Master Threshold'!E23 -> 20 | E36: 0 | F36: 191 | G36: 191 | H36: 0 | I36: 191 | J36: =H36+I36 -> 191 | K36: =IF(COUNTA(G36,J36)=0,"",IF(J36-G36=0,0,IF(J36-G36>0,"+"&(J36-G36),J36-G36))) -> 0 | L36: =IF(D36=0,"—",IF(J36<=D36,"🔴 KRITIS",IF(J36<=D36*2,"🟠 HAMPIR HABIS","🟢 AMAN"))) -> 🟢 AMAN
A37: 24 | B37: Kaldu Odeng | C37: gr-+ | D37: ='⚙️ Master Threshold'!E29 -> 100 | E37: 0 | F37: 328 | G37: 328 | H37: 0 | I37: 328 | J37: =H37+I37 -> 328 | K37: =IF(COUNTA(G37,J37)=0,"",IF(J37-G37=0,0,IF(J37-G37>0,"+"&(J37-G37),J37-G37))) -> 0 | L37: =IF(D37=0,"—",IF(J37<=D37,"🔴 KRITIS",IF(J37<=D37*2,"🟠 HAMPIR HABIS","🟢 AMAN"))) -> 🟢 AMAN
A38: 26 | B38: Teh Tong Ji | C38: pcs | D38: ='⚙️ Master Threshold'!E31 -> 3 | E38: 0 | F38: 23 | G38: 23 | H38: 0 | I38: 23 | J38: =H38+I38 -> 23 | K38: =IF(COUNTA(G38,J38)=0,"",IF(J38-G38=0,0,IF(J38-G38>0,"+"&(J38-G38),J38-G38))) -> 0 | L38: =IF(D38=0,"—",IF(J38<=D38,"🔴 KRITIS",IF(J38<=D38*2,"🟠 HAMPIR HABIS","🟢 AMAN"))) -> 🟢 AMAN
B39: ▶ AREA MEJA BIRU DEPAN | K39: =IF(COUNTA(G39,J39)=0,"",IF(J39-G39=0,0,IF(J39-G39>0,"+"&(J39-G39),J39-G39)))
B42: ▶ AREA CHILLER | K42: =IF(COUNTA(G42,J42)=0,"",IF(J42-G42=0,0,IF(J42-G42>0,"+"&(J42-G42),J42-G42)))
...

Sheet ⚙️ Master Threshold
A1: ⚙️ MASTER THRESHOLD — Atur Semua Batas Minimum Stok di Sini
A2: ✏️ Ubah angka di kolom THRESHOLD BARU. lalu simpan file. Semua sheet SO akan otomatis mengikuti.
A4: No | B4: NAMA BARANG | C4: AREA / LOKASI | D4: THRESHOLD SAAT INI | E4: THRESHOLD BARU ✏️ | F4: KETERANGAN / CATATAN
A5: ▶ MEJA BIRU DEPAN + CHILLER
A6: 1 | B6: Tepung Terigu | C6: Meja Biru + Chiller | D6: ='Meja Biru + Chiller'!D7 -> #REF! | E6: 2
A7: 2 | B7: Bumbu Mix | C7: Meja Biru + Chiller | D7: ='Meja Biru + Chiller'!D8 -> #REF! | E7: 1
A8: 3 | B8: Minyak Beku | C8: Meja Biru + Chiller | D8: ='Meja Biru + Chiller'!D9 -> #REF! | E8: 5
A9: 4 | B9: Bumbu Marinasi | C9: Meja Biru + Chiller | D9: ='Meja Biru + Chiller'!D10 -> #REF! | E9: 125
A10: 5 | B10: Beras | C10: Meja Biru + Chiller | D10: ='Meja Biru + Chiller'!D11 -> #REF! | E10: 1
A11: 6 | B11: Mango Mint | C11: Meja Biru + Chiller | D11: ='Meja Biru + Chiller'!D12 -> #REF! | E11: 8
A12: 7 | B12: Mint Ice Cream | C12: Meja Biru + Chiller | D12: ='Meja Biru + Chiller'!D13 -> #REF! | E12: 8
A13: 8 | B13: Vanilla Rose | C13: Meja Biru + Chiller | D13: ='Meja Biru + Chiller'!D14 -> #REF! | E13: 8
A14: 9 | B14: Snowy Cheese | C14: Meja Biru + Chiller | D14: ='Meja Biru + Chiller'!D15 -> #REF! | E14: =380 -> 380
A15: 10 | B15: Tepung Panir | C15: Meja Biru + Chiller | D15: ='Meja Biru + Chiller'!D16 -> #REF! | E15: 125
A16: 11 | B16: Tepung Corndog | C16: Meja Biru + Chiller | D16: ='Meja Biru + Chiller'!D17 -> #REF! | E16: 0
A17: 12 | B17: Cabe Sachet | C17: Meja Biru + Chiller | D17: ='Meja Biru + Chiller'!D18 -> #REF! | E17: 10
A18: 13 | B18: Tomat Sachet | C18: Meja Biru + Chiller | D18: ='Meja Biru + Chiller'!D19 -> #REF! | E18: 10
A19: 14 | B19: Nori | C19: Meja Biru + Chiller | D19: ='Meja Biru + Chiller'!D20 -> #REF! | E19: =30 -> 30
A20: 15 | B20: Biji Wijen | C20: Meja Biru + Chiller | D20: ='Meja Biru + Chiller'!D21 -> #REF! | E20: =30 -> 30
A21: 16 | B21: Gula Putih | C21: Meja Biru + Chiller | D21: ='Meja Biru + Chiller'!D22 -> #REF! | E21: =100 -> 100
A22: 17 | B22: Garam | C22: Meja Biru + Chiller | D22: ='Meja Biru + Chiller'!D23 -> #REF! | E22: =20 -> 20
A23: 18 | B23: Cajun | C23: Meja Biru + Chiller | D23: ='Meja Biru + Chiller'!D25 -> #REF! | E23: =20 -> 20
A24: 19 | B24: Samyang | C24: Meja Biru + Chiller | D24: ='Meja Biru + Chiller'!D26 -> #REF! | E24: =45 -> 45
A25: 20 | B25: Bon Cabe | C25: Meja Biru + Chiller | D25: ='Meja Biru + Chiller'!D27 -> #REF! | E25: 1
A26: 21 | B26: Plastik 15 | C26: Meja Biru + Chiller | D26: ='Meja Biru + Chiller'!D28 -> #REF! | E26: 1
A27: 22 | B27: Plastik 24 | C27: Meja Biru + Chiller | D27: ='Meja Biru + Chiller'!D29 -> #REF! | E27: 1
A28: 23 | B28: Plastik 30 | C28: Meja Biru + Chiller | D28: ='Meja Biru + Chiller'!D30 -> #REF! | E28: 1
A29: 24 | B29: Kaldu Odeng | C29: Meja Biru + Chiller | D29: ='Meja Biru + Chiller'!D31 -> #REF! | E29: =100 -> 100
A30: 25 | B30: Baking Soda | C30: Meja Biru + Chiller | D30: ='Meja Biru + Chiller'!D32 -> #REF! | E30: 0
A31: 26 | B31: Teh Tong Ji | C31: Meja Biru + Chiller | D31: ='Meja Biru + Chiller'!D33 -> #REF! | E31: 3
A32: 27 | B32: Dus Hampers | C32: Meja Biru + Chiller | D32: ='Meja Biru + Chiller'!D34 -> #REF! | E32: 0
A33: 28 | B33: Box Berbagi | C33: Meja Biru + Chiller | D33: ='Meja Biru + Chiller'!D35 -> #REF! | E33: 0
A34: 29 | B34: Botol Hampers | C34: Meja Biru + Chiller | D34: ='Meja Biru + Chiller'!D36 -> #REF! | E34: 0
A35: 30 | B35: Gas Torch | C35: Meja Biru + Chiller | D35: ='Meja Biru + Chiller'!D37 -> #REF! | E35: =100 -> 100
A36: 31 | B36: Katsubuoshi | C36: Meja Biru + Chiller | D36: ='Meja Biru + Chiller'!D38 -> #REF! | E36: 5
A37: 32 | B37: Spray Lemon Pepper | C37: Meja Biru + Chiller | D37: ='Meja Biru + Chiller'!D39 -> #REF! | E37: 40
A38: 33 | B38: Minyak Truffel | C38: Meja Biru + Chiller | D38: ='Meja Biru + Chiller'!D52 -> #REF! | E38: 100
A39: =A38+1 -> 34 | B39: Ultra (susu) | C39: Meja Biru + Chiller | D39: ='Meja Biru + Chiller'!D45 -> #REF! | E39: 250
A40: =A39+1 -> 35 | B40: Air Gula | C40: Meja Biru + Chiller | D40: ='Meja Biru + Chiller'!D46 -> #REF! | E40: 100
A41: =A40+1 -> 36 | B41: Mozzarella | C41: Meja Biru + Chiller | D41: ='Meja Biru + Chiller'!D53 -> #REF! | E41: 200
...
